<?xml version="1.0" encoding="UTF-8"?>
<robot name="diff_summer_robot">
    <material name="green">
        <color rgba="0.5 0.0 0.5 1"/>
    </material>
    <material name="red">
        <color rgba="0.1 0.0 0.0 1"/>
    </material>
    <link name="base_link">
        <visual>
            <geometry>
                <box size="0.6 0.4 0.2"/>
            </geometry>
            <origin xyz="0 0 0.1" rpy="0 0 0"/>
            <material name="purple">
                <color rgba="0.5 0.0 0.5 1"/>
            </material>
        </visual>    
    </link>

    <link name="third_link">
        <visual>
            <geometry>
                <box size="0.1 0.1 0.1"/>
            </geometry>
            <origin xyz="0.0 0 0.05" rpy="0 0 0"/>
            <material name="red"/> 
        </visual>
    </link>

    <link name="second_link">
        <visual>
            <geometry>
                <cylinder radius="0.1" length="0.1"/>
            </geometry>
            <origin xyz="0.0 0 0.05" rpy="0 0 0"/>
            <material name="green"/>
        </visual>
    </link>
    <joint name="base_to_second" type="continuous">
        <parent link="base_link"/>
        <child link="second_link"/>
        <origin xyz="0.0 0 0.2" rpy="0 0 0"/>
        <limit lower="-1.57" upper="1.57" effort="10.0" velocity="3.14"/>
        <axis xyz="0.0 0.0 1"/>
    </joint>
    <joint name="second_to_third" type="prismatic">
        <parent link="second_link"/>
        <child link="third_link"/>
        <origin xyz="0.0 0 0.1" rpy="0 0 0"/>
        <limit lower="0.0" upper="0.2" effort="10.0" velocity="0.05"/>
        <axis xyz="1 0.0 0.0"/>
    </joint>

</robot>